falha encontrada
WARNING:root:{'name': 'kube-znn-64cd6996dd-nkxrv.167f40577ea6700c', 'type': 'Warning', 'message': '0/1 nodes are available: 1 Insufficient cpu.', 'dateevent': '2021-05-15 13:25:35+00:00'}
falha encontrada
WARNING:root:{'name': 'kube-znn-644ff8f5d6-z4k2l.167f405895630f00', 'type': 'Warning', 'message': '0/1 nodes are available: 1 Insufficient cpu.', 'dateevent': '2021-05-15 13:25:40+00:00'}
falha encontrada
WARNING:root:{'name': 'kube-znn-644ff8f5d6-z4k2l.167f405895630f00', 'type': 'Warning', 'message': '0/1 nodes are available: 1 Insufficient cpu.', 'dateevent': '2021-05-15 13:25:40+00:00'}
falha encontrada
WARNING:root:{'name': 'kube-znn-644ff8f5d6-skzmd.167f405898c71a49', 'type': 'Warning', 'message': '0/1 nodes are available: 1 Insufficient cpu.', 'dateevent': '2021-05-15 13:25:40+00:00'}
falha encontrada
WARNING:root:{'name': 'kube-znn-644ff8f5d6-skzmd.167f405898c71a49', 'type': 'Warning', 'message': '0/1 nodes are available: 1 Insufficient cpu.', 'dateevent': '2021-05-15 13:25:40+00:00'}
falha encontrada
WARNING:root:{'name': 'kube-znn-64cd6996dd-tjn5w.167f4058a086c3f8', 'type': 'Warning', 'message': '0/1 nodes are available: 1 Insufficient cpu.', 'dateevent': '2021-05-15 13:25:40+00:00'}
falha encontrada
WARNING:root:{'name': 'kube-znn-64cd6996dd-ssbdf.167f4058a2703355', 'type': 'Warning', 'message': '0/1 nodes are available: 1 Insufficient cpu.', 'dateevent': '2021-05-15 13:25:40+00:00'}
falha encontrada
WARNING:root:{'name': 'kube-znn-64cd6996dd-ssbdf.167f4058a2703355', 'type': 'Warning', 'message': '0/1 nodes are available: 1 Insufficient cpu.', 'dateevent': '2021-05-15 13:25:40+00:00'}
falha encontrada
WARNING:root:{'name': 'kube-znn-644ff8f5d6-w5gs9.167f4059c12c23e6', 'type': 'Warning', 'message': '0/1 nodes are available: 1 Insufficient cpu.', 'dateevent': '2021-05-15 13:25:45+00:00'}
falha encontrada
WARNING:root:{'name': 'kube-znn-644ff8f5d6-w5gs9.167f4059c12c23e6', 'type': 'Warning', 'message': '0/1 nodes are available: 1 Insufficient cpu.', 'dateevent': '2021-05-15 13:25:45+00:00'}
falha encontrada
WARNING:root:{'name': 'kube-znn-644ff8f5d6-l8jcl.167f4059c7598050', 'type': 'Warning', 'message': '0/1 nodes are available: 1 Insufficient cpu.', 'dateevent': '2021-05-15 13:25:45+00:00'}
WARNING:root:{'name': 'kube-znn-64cd6996dd-m8ff4.167f4059cf37bc2c', 'type': 'Warning', 'message': '0/1 nodes are available: 1 Insufficient cpu.', 'dateevent': '2021-05-15 13:25:45+00:00'}
falha encontrada
falha encontrada
WARNING:root:{'name': 'kube-znn-64cd6996dd-m8ff4.167f4059cf37bc2c', 'type': 'Warning', 'message': '0/1 nodes are available: 1 Insufficient cpu.', 'dateevent': '2021-05-15 13:25:45+00:00'}
falha encontrada
WARNING:root:{'name': 'kube-znn-64cd6996dd-vprrx.167f4059d33bdac7', 'type': 'Warning', 'message': '0/1 nodes are available: 1 Insufficient cpu.', 'dateevent': '2021-05-15 13:25:45+00:00'}
falha encontrada
WARNING:root:{'name': 'kube-znn-64cd6996dd-vprrx.167f4059d33bdac7', 'type': 'Warning', 'message': '0/1 nodes are available: 1 Insufficient cpu.', 'dateevent': '2021-05-15 13:25:45+00:00'}
falha encontrada
WARNING:root:{'name': 'kube-znn-64cd6996dd-vprrx.167f4059d33bdac7', 'type': 'Warning', 'message': '0/1 nodes are available: 1 Insufficient cpu.', 'dateevent': '2021-05-15 13:25:45+00:00'}
falha encontrada
WARNING:root:{'name': 'kube-znn-64cd6996dd-98pgv.167f405afc0daafa', 'type': 'Warning', 'message': '0/1 nodes are available: 1 Insufficient cpu.', 'dateevent': '2021-05-15 13:25:50+00:00'}
falha encontrada
WARNING:root:{'name': 'kube-znn-64cd6996dd-98pgv.167f405afc0daafa', 'type': 'Warning', 'message': '0/1 nodes are available: 1 Insufficient cpu.', 'dateevent': '2021-05-15 13:25:50+00:00'}
falha encontrada
WARNING:root:{'name': 'kube-znn-64cd6996dd-7v48l.167f405b04233eb6', 'type': 'Warning', 'message': '0/1 nodes are available: 1 Insufficient cpu.', 'dateevent': '2021-05-15 13:25:50+00:00'}
falha encontrada
WARNING:root:{'name': 'kube-znn-64cd6996dd-7v48l.167f405b04233eb6', 'type': 'Warning', 'message': '0/1 nodes are available: 1 Insufficient cpu.', 'dateevent': '2021-05-15 13:25:50+00:00'}
falha encontrada
WARNING:root:{'name': 'kube-znn-64cd6996dd-7v48l.167f405b04233eb6', 'type': 'Warning', 'message': '0/1 nodes are available: 1 Insufficient cpu.', 'dateevent': '2021-05-15 13:25:50+00:00'}
WARNING:root:{'name': 'kube-znn-644ff8f5d6-bbwmw.167f405c1691623f', 'type': 'Warning', 'message': '0/1 nodes are available: 1 Insufficient cpu.', 'dateevent': '2021-05-15 13:25:55+00:00'}
falha encontrada
falha encontrada
WARNING:root:{'name': 'kube-znn-644ff8f5d6-bbwmw.167f405c1691623f', 'type': 'Warning', 'message': '0/1 nodes are available: 1 Insufficient cpu.', 'dateevent': '2021-05-15 13:25:55+00:00'}
falha encontrada
WARNING:root:{'name': 'kube-znn-64cd6996dd-gtvhx.167f405c27435ab3', 'type': 'Warning', 'message': '0/1 nodes are available: 1 Insufficient cpu.', 'dateevent': '2021-05-15 13:25:55+00:00'}
falha encontrada
WARNING:root:{'name': 'kube-znn-64cd6996dd-kmk54.167f405c2ba2591d', 'type': 'Warning', 'message': '0/1 nodes are available: 1 Insufficient cpu.', 'dateevent': '2021-05-15 13:25:55+00:00'}
falha encontrada
WARNING:root:{'name': 'kube-znn-64cd6996dd-kmk54.167f405c2ba2591d', 'type': 'Warning', 'message': '0/1 nodes are available: 1 Insufficient cpu.', 'dateevent': '2021-05-15 13:25:55+00:00'}
falha encontrada
WARNING:root:{'name': 'kube-znn-644ff8f5d6-6jqls.167f405d439dabf7', 'type': 'Warning', 'message': '0/1 nodes are available: 1 Insufficient cpu.', 'dateevent': '2021-05-15 13:26:00+00:00'}
falha encontrada
WARNING:root:{'name': 'kube-znn-644ff8f5d6-6jqls.167f405d439dabf7', 'type': 'Warning', 'message': '0/1 nodes are available: 1 Insufficient cpu.', 'dateevent': '2021-05-15 13:26:00+00:00'}
WARNING:root:{'name': 'kube-znn-64cd6996dd-dcdth.167f405d5601604c', 'type': 'Warning', 'message': '0/1 nodes are available: 1 Insufficient cpu.', 'dateevent': '2021-05-15 13:26:00+00:00'}
falha encontrada
WARNING:root:{'name': 'kube-znn-64cd6996dd-dcdth.167f405d5601604c', 'type': 'Warning', 'message': '0/1 nodes are available: 1 Insufficient cpu.', 'dateevent': '2021-05-15 13:26:00+00:00'}
falha encontrada
falha encontrada
WARNING:root:{'name': 'kube-znn-64cd6996dd-rqlzr.167f405d5d3601ce', 'type': 'Warning', 'message': '0/1 nodes are available: 1 Insufficient cpu.', 'dateevent': '2021-05-15 13:26:00+00:00'}
falha encontrada
WARNING:root:{'name': 'kube-znn-64cd6996dd-rqlzr.167f405d5d3601ce', 'type': 'Warning', 'message': '0/1 nodes are available: 1 Insufficient cpu.', 'dateevent': '2021-05-15 13:26:00+00:00'}
falha encontrada
WARNING:root:{'name': 'kube-znn-644ff8f5d6-jqvj9.167f405e66f7106e', 'type': 'Warning', 'message': '0/1 nodes are available: 1 Insufficient cpu.', 'dateevent': '2021-05-15 13:26:05+00:00'}
falha encontrada
WARNING:root:{'name': 'kube-znn-644ff8f5d6-jqvj9.167f405e66f7106e', 'type': 'Warning', 'message': '0/1 nodes are available: 1 Insufficient cpu.', 'dateevent': '2021-05-15 13:26:05+00:00'}
WARNING:root:{'name': 'kube-znn-644ff8f5d6-dktpk.167f405e6d9dcdc2', 'type': 'Warning', 'message': '0/1 nodes are available: 1 Insufficient cpu.', 'dateevent': '2021-05-15 13:26:05+00:00'}
falha encontrada
WARNING:root:{'name': 'kube-znn-644ff8f5d6-dktpk.167f405e6d9dcdc2', 'type': 'Warning', 'message': '0/1 nodes are available: 1 Insufficient cpu.', 'dateevent': '2021-05-15 13:26:05+00:00'}
falha encontrada
falha encontrada
WARNING:root:{'name': 'kube-znn-64cd6996dd-87xwc.167f405e7bd253d0', 'type': 'Warning', 'message': '0/1 nodes are available: 1 Insufficient cpu.', 'dateevent': '2021-05-15 13:26:05+00:00'}
falha encontrada
WARNING:root:{'name': 'kube-znn-64cd6996dd-87xwc.167f405e7bd253d0', 'type': 'Warning', 'message': '0/1 nodes are available: 1 Insufficient cpu.', 'dateevent': '2021-05-15 13:26:05+00:00'}
falha encontrada
WARNING:root:{'name': 'kube-znn-64cd6996dd-6zkwf.167f405e7fce3d2e', 'type': 'Warning', 'message': '0/1 nodes are available: 1 Insufficient cpu.', 'dateevent': '2021-05-15 13:26:05+00:00'}
falha encontrada
WARNING:root:{'name': 'kube-znn-64cd6996dd-6zkwf.167f405e7fce3d2e', 'type': 'Warning', 'message': '0/1 nodes are available: 1 Insufficient cpu.', 'dateevent': '2021-05-15 13:26:05+00:00'}
falha encontrada
WARNING:root:{'name': 'kube-znn-64cd6996dd-6zkwf.167f405e7fce3d2e', 'type': 'Warning', 'message': '0/1 nodes are available: 1 Insufficient cpu.', 'dateevent': '2021-05-15 13:26:05+00:00'}
falha encontrada
WARNING:root:{'name': 'kube-znn-644ff8f5d6-xxdbq.167f405f8c9a3d33', 'type': 'Warning', 'message': '0/1 nodes are available: 1 Insufficient cpu.', 'dateevent': '2021-05-15 13:26:10+00:00'}
WARNING:root:{'name': 'kube-znn-64cd6996dd-sgrdb.167f405f974a65bd', 'type': 'Warning', 'message': '0/1 nodes are available: 1 Insufficient cpu.', 'dateevent': '2021-05-15 13:26:10+00:00'}
falha encontrada
WARNING:root:{'name': 'kube-znn-64cd6996dd-sjrsh.167f405f9bb770fa', 'type': 'Warning', 'message': '0/1 nodes are available: 1 Insufficient cpu.', 'dateevent': '2021-05-15 13:26:10+00:00'}
falha encontrada
falha encontrada
WARNING:root:{'name': 'kube-znn-64cd6996dd-sjrsh.167f405f9bb770fa', 'type': 'Warning', 'message': '0/1 nodes are available: 1 Insufficient cpu.', 'dateevent': '2021-05-15 13:26:10+00:00'}
falha encontrada
WARNING:root:{'name': 'kube-znn-64cd6996dd-sjrsh.167f405f9bb770fa', 'type': 'Warning', 'message': '0/1 nodes are available: 1 Insufficient cpu.', 'dateevent': '2021-05-15 13:26:10+00:00'}
WARNING:root:{'name': 'kube-znn-644ff8f5d6-44pbj.167f4060b6d23ebc', 'type': 'Warning', 'message': '0/1 nodes are available: 1 Insufficient cpu.', 'dateevent': '2021-05-15 13:26:15+00:00'}
falha encontrada
falha encontrada
WARNING:root:{'name': 'kube-znn-64cd6996dd-44kvn.167f4060bf1a7070', 'type': 'Warning', 'message': '0/1 nodes are available: 1 Insufficient cpu.', 'dateevent': '2021-05-15 13:26:15+00:00'}
WARNING:root:{'name': 'kube-znn-64cd6996dd-xqbt5.167f4060c10b33ed', 'type': 'Warning', 'message': '0/1 nodes are available: 1 Insufficient cpu.', 'dateevent': '2021-05-15 13:26:15+00:00'}
falha encontrada
WARNING:root:{'name': 'kube-znn-64cd6996dd-xqbt5.167f4060c10b33ed', 'type': 'Warning', 'message': '0/1 nodes are available: 1 Insufficient cpu.', 'dateevent': '2021-05-15 13:26:15+00:00'}
falha encontrada
falha encontrada
WARNING:root:{'name': 'kube-znn-644ff8f5d6-vm4x2.167f4061e1594974', 'type': 'Warning', 'message': '0/1 nodes are available: 1 Insufficient cpu.', 'dateevent': '2021-05-15 13:26:20+00:00'}
falha encontrada
WARNING:root:{'name': 'kube-znn-644ff8f5d6-vm4x2.167f4061e1594974', 'type': 'Warning', 'message': '0/1 nodes are available: 1 Insufficient cpu.', 'dateevent': '2021-05-15 13:26:20+00:00'}
falha encontrada
WARNING:root:{'name': 'kube-znn-644ff8f5d6-dzshf.167f4061e4b25fb1', 'type': 'Warning', 'message': '0/1 nodes are available: 1 Insufficient cpu.', 'dateevent': '2021-05-15 13:26:20+00:00'}
falha encontrada
WARNING:root:{'name': 'kube-znn-644ff8f5d6-dzshf.167f4061e4b25fb1', 'type': 'Warning', 'message': '0/1 nodes are available: 1 Insufficient cpu.', 'dateevent': '2021-05-15 13:26:20+00:00'}
falha encontrada
WARNING:root:{'name': 'kube-znn-64cd6996dd-kbpf6.167f4061eae46d90', 'type': 'Warning', 'message': '0/1 nodes are available: 1 Insufficient cpu.', 'dateevent': '2021-05-15 13:26:20+00:00'}
falha encontrada
WARNING:root:{'name': 'kube-znn-64cd6996dd-vm5gx.167f4061ed8eb384', 'type': 'Warning', 'message': '0/1 nodes are available: 1 Insufficient cpu.', 'dateevent': '2021-05-15 13:26:20+00:00'}
falha encontrada
WARNING:root:{'name': 'kube-znn-64cd6996dd-kbpf6.167f4061eae46d90', 'type': 'Warning', 'message': '0/1 nodes are available: 1 Insufficient cpu.', 'dateevent': '2021-05-15 13:26:20+00:00'}
falha encontrada
WARNING:root:{'name': 'kube-znn-644ff8f5d6-4pmx5.167f40630d50bbe6', 'type': 'Warning', 'message': '0/1 nodes are available: 1 Insufficient cpu.', 'dateevent': '2021-05-15 13:26:25+00:00'}
WARNING:root:{'name': 'kube-znn-644ff8f5d6-4pmx5.167f40630d50bbe6', 'type': 'Warning', 'message': '0/1 nodes are available: 1 Insufficient cpu.', 'dateevent': '2021-05-15 13:26:25+00:00'}
falha encontrada
WARNING:root:{'name': 'kube-znn-644ff8f5d6-cswss.167f406312445ba6', 'type': 'Warning', 'message': '0/1 nodes are available: 1 Insufficient cpu.', 'dateevent': '2021-05-15 13:26:25+00:00'}
falha encontrada
falha encontrada
WARNING:root:{'name': 'kube-znn-644ff8f5d6-cswss.167f406312445ba6', 'type': 'Warning', 'message': '0/1 nodes are available: 1 Insufficient cpu.', 'dateevent': '2021-05-15 13:26:25+00:00'}
falha encontrada
WARNING:root:{'name': 'kube-znn-64cd6996dd-lf46s.167f40631c7cea60', 'type': 'Warning', 'message': '0/1 nodes are available: 1 Insufficient cpu.', 'dateevent': '2021-05-15 13:26:25+00:00'}
falha encontrada
WARNING:root:{'name': 'kube-znn-64cd6996dd-lf46s.167f40631c7cea60', 'type': 'Warning', 'message': '0/1 nodes are available: 1 Insufficient cpu.', 'dateevent': '2021-05-15 13:26:25+00:00'}
falha encontrada
WARNING:root:{'name': 'kube-znn-64cd6996dd-x7x4d.167f40631e7f113e', 'type': 'Warning', 'message': '0/1 nodes are available: 1 Insufficient cpu.', 'dateevent': '2021-05-15 13:26:25+00:00'}
falha encontrada
WARNING:root:{'name': 'kube-znn-64cd6996dd-x7x4d.167f40631e7f113e', 'type': 'Warning', 'message': '0/1 nodes are available: 1 Insufficient cpu.', 'dateevent': '2021-05-15 13:26:25+00:00'}
falha encontrada
WARNING:root:{'name': 'kube-znn-644ff8f5d6-lzfd6.167f40643600ebf0', 'type': 'Warning', 'message': '0/1 nodes are available: 1 Insufficient cpu.', 'dateevent': '2021-05-15 13:26:30+00:00'}
WARNING:root:{'name': 'kube-znn-644ff8f5d6-lzfd6.167f40643600ebf0', 'type': 'Warning', 'message': '0/1 nodes are available: 1 Insufficient cpu.', 'dateevent': '2021-05-15 13:26:30+00:00'}
falha encontrada
falha encontrada
WARNING:root:{'name': 'kube-znn-64cd6996dd-2vt5h.167f406444f186c9', 'type': 'Warning', 'message': '0/1 nodes are available: 1 Insufficient cpu.', 'dateevent': '2021-05-15 13:26:30+00:00'}
falha encontrada
WARNING:root:{'name': 'kube-znn-64cd6996dd-2vt5h.167f406444f186c9', 'type': 'Warning', 'message': '0/1 nodes are available: 1 Insufficient cpu.', 'dateevent': '2021-05-15 13:26:30+00:00'}
falha encontrada
WARNING:root:{'name': 'kube-znn-64cd6996dd-trnkh.167f406447b87e2b', 'type': 'Warning', 'message': '0/1 nodes are available: 1 Insufficient cpu.', 'dateevent': '2021-05-15 13:26:30+00:00'}
falha encontrada
WARNING:root:{'name': 'kube-znn-644ff8f5d6-qwzpj.167f40655b91cdfc', 'type': 'Warning', 'message': '0/1 nodes are available: 1 Insufficient cpu.', 'dateevent': '2021-05-15 13:26:34+00:00'}
falha encontrada
WARNING:root:{'name': 'kube-znn-644ff8f5d6-486ns.167f40655cd7a9d1', 'type': 'Warning', 'message': '0/1 nodes are available: 1 Insufficient cpu.', 'dateevent': '2021-05-15 13:26:34+00:00'}
falha encontrada
WARNING:root:{'name': 'kube-znn-644ff8f5d6-486ns.167f40655cd7a9d1', 'type': 'Warning', 'message': '0/1 nodes are available: 1 Insufficient cpu.', 'dateevent': '2021-05-15 13:26:34+00:00'}
falha encontrada
WARNING:root:{'name': 'kube-znn-64cd6996dd-clw57.167f4065657fb614', 'type': 'Warning', 'message': '0/1 nodes are available: 1 Insufficient cpu.', 'dateevent': '2021-05-15 13:26:35+00:00'}
falha encontrada
WARNING:root:{'name': 'kube-znn-64cd6996dd-lrkdt.167f406567314ca7', 'type': 'Warning', 'message': '0/1 nodes are available: 1 Insufficient cpu.', 'dateevent': '2021-05-15 13:26:35+00:00'}
falha encontrada
WARNING:root:{'name': 'kube-znn-64cd6996dd-lrkdt.167f406567314ca7', 'type': 'Warning', 'message': '0/1 nodes are available: 1 Insufficient cpu.', 'dateevent': '2021-05-15 13:26:35+00:00'}
WARNING:root:{'name': 'kube-znn-644ff8f5d6-8rxjk.167f406686cf9455', 'type': 'Warning', 'message': '0/1 nodes are available: 1 Insufficient cpu.', 'dateevent': '2021-05-15 13:26:39+00:00'}
falha encontrada
WARNING:root:{'name': 'kube-znn-644ff8f5d6-8rxjk.167f406686cf9455', 'type': 'Warning', 'message': '0/1 nodes are available: 1 Insufficient cpu.', 'dateevent': '2021-05-15 13:26:39+00:00'}
falha encontrada
falha encontrada
WARNING:root:{'name': 'kube-znn-644ff8f5d6-452lg.167f40668971cf7e', 'type': 'Warning', 'message': '0/1 nodes are available: 1 Insufficient cpu.', 'dateevent': '2021-05-15 13:26:40+00:00'}
falha encontrada
WARNING:root:{'name': 'kube-znn-64cd6996dd-zg27w.167f40668e34cbfb', 'type': 'Warning', 'message': '0/1 nodes are available: 1 Insufficient cpu.', 'dateevent': '2021-05-15 13:26:40+00:00'}
falha encontrada
WARNING:root:{'name': 'kube-znn-64cd6996dd-dff2n.167f406690d5dea8', 'type': 'Warning', 'message': '0/1 nodes are available: 1 Insufficient cpu.', 'dateevent': '2021-05-15 13:26:40+00:00'}
falha encontrada
WARNING:root:{'name': 'kube-znn-64cd6996dd-dff2n.167f406690d5dea8', 'type': 'Warning', 'message': '0/1 nodes are available: 1 Insufficient cpu.', 'dateevent': '2021-05-15 13:26:40+00:00'}
falha encontrada
WARNING:root:{'name': 'kube-znn-644ff8f5d6-qqvfk.167f4067afbec61f', 'type': 'Warning', 'message': '0/1 nodes are available: 1 Insufficient cpu.', 'dateevent': '2021-05-15 13:26:44+00:00'}
falha encontrada
WARNING:root:{'name': 'kube-znn-644ff8f5d6-qqvfk.167f4067afbec61f', 'type': 'Warning', 'message': '0/1 nodes are available: 1 Insufficient cpu.', 'dateevent': '2021-05-15 13:26:44+00:00'}
falha encontrada
WARNING:root:{'name': 'kube-znn-644ff8f5d6-ncrbp.167f4067b26c477f', 'type': 'Warning', 'message': '0/1 nodes are available: 1 Insufficient cpu.', 'dateevent': '2021-05-15 13:26:45+00:00'}
falha encontrada
WARNING:root:{'name': 'kube-znn-644ff8f5d6-ncrbp.167f4067b26c477f', 'type': 'Warning', 'message': '0/1 nodes are available: 1 Insufficient cpu.', 'dateevent': '2021-05-15 13:26:45+00:00'}
falha encontrada
WARNING:root:{'name': 'kube-znn-64cd6996dd-9f9zx.167f4067b8fcfeee', 'type': 'Warning', 'message': '0/1 nodes are available: 1 Insufficient cpu.', 'dateevent': '2021-05-15 13:26:45+00:00'}
falha encontrada
WARNING:root:{'name': 'kube-znn-64cd6996dd-f7j6g.167f4067ba7b31d8', 'type': 'Warning', 'message': '0/1 nodes are available: 1 Insufficient cpu.', 'dateevent': '2021-05-15 13:26:45+00:00'}
falha encontrada
WARNING:root:{'name': 'kube-znn-64cd6996dd-f7j6g.167f4067ba7b31d8', 'type': 'Warning', 'message': '0/1 nodes are available: 1 Insufficient cpu.', 'dateevent': '2021-05-15 13:26:45+00:00'}
falha encontrada
WARNING:root:{'name': 'kube-znn-644ff8f5d6-5mcfp.167f4068de3f1d58', 'type': 'Warning', 'message': '0/1 nodes are available: 1 Insufficient cpu.', 'dateevent': '2021-05-15 13:26:50+00:00'}
falha encontrada
WARNING:root:{'name': 'kube-znn-644ff8f5d6-5mcfp.167f4068de3f1d58', 'type': 'Warning', 'message': '0/1 nodes are available: 1 Insufficient cpu.', 'dateevent': '2021-05-15 13:26:50+00:00'}
falha encontrada
WARNING:root:{'name': 'kube-znn-64cd6996dd-5r46x.167f4068f0edf697', 'type': 'Warning', 'message': '0/1 nodes are available: 1 Insufficient cpu.', 'dateevent': '2021-05-15 13:26:50+00:00'}
falha encontrada
WARNING:root:{'name': 'kube-znn-64cd6996dd-tztp7.167f4068f49e7f05', 'type': 'Warning', 'message': '0/1 nodes are available: 1 Insufficient cpu.', 'dateevent': '2021-05-15 13:26:50+00:00'}
WARNING:root:{'name': 'kube-znn-64cd6996dd-tztp7.167f4068f49e7f05', 'type': 'Warning', 'message': '0/1 nodes are available: 1 Insufficient cpu.', 'dateevent': '2021-05-15 13:26:50+00:00'}
falha encontrada
falha encontrada
WARNING:root:{'name': 'kube-znn-644ff8f5d6-798rs.167f406a03c51052', 'type': 'Warning', 'message': '0/1 nodes are available: 1 Insufficient cpu.', 'dateevent': '2021-05-15 13:26:54+00:00'}
falha encontrada
WARNING:root:{'name': 'kube-znn-644ff8f5d6-798rs.167f406a03c51052', 'type': 'Warning', 'message': '0/1 nodes are available: 1 Insufficient cpu.', 'dateevent': '2021-05-15 13:26:54+00:00'}
falha encontrada
WARNING:root:{'name': 'kube-znn-644ff8f5d6-jzf75.167f406a066f76af', 'type': 'Warning', 'message': '0/1 nodes are available: 1 Insufficient cpu.', 'dateevent': '2021-05-15 13:26:54+00:00'}
falha encontrada
WARNING:root:{'name': 'kube-znn-644ff8f5d6-jzf75.167f406a066f76af', 'type': 'Warning', 'message': '0/1 nodes are available: 1 Insufficient cpu.', 'dateevent': '2021-05-15 13:26:54+00:00'}
falha encontrada
WARNING:root:{'name': 'kube-znn-64cd6996dd-7hsnl.167f406a0dd3ddae', 'type': 'Warning', 'message': '0/1 nodes are available: 1 Insufficient cpu.', 'dateevent': '2021-05-15 13:26:55+00:00'}
falha encontrada
WARNING:root:{'name': 'kube-znn-64cd6996dd-fzxkf.167f406a0ff35d05', 'type': 'Warning', 'message': '0/1 nodes are available: 1 Insufficient cpu.', 'dateevent': '2021-05-15 13:26:55+00:00'}
falha encontrada
WARNING:root:{'name': 'kube-znn-64cd6996dd-fzxkf.167f406a0ff35d05', 'type': 'Warning', 'message': '0/1 nodes are available: 1 Insufficient cpu.', 'dateevent': '2021-05-15 13:26:55+00:00'}
falha encontrada
WARNING:root:{'name': 'kube-znn-64cd6996dd-fzxkf.167f406a0ff35d05', 'type': 'Warning', 'message': '0/1 nodes are available: 1 Insufficient cpu.', 'dateevent': '2021-05-15 13:26:55+00:00'}
falha encontrada
WARNING:root:{'name': 'kube-znn-644ff8f5d6-ghq22.167f406b2f1ef32f', 'type': 'Warning', 'message': '0/1 nodes are available: 1 Insufficient cpu.', 'dateevent': '2021-05-15 13:26:59+00:00'}
WARNING:root:{'name': 'kube-znn-644ff8f5d6-r4j2k.167f406b338178e8', 'type': 'Warning', 'message': '0/1 nodes are available: 1 Insufficient cpu.', 'dateevent': '2021-05-15 13:27:00+00:00'}
falha encontrada
falha encontrada
WARNING:root:{'name': 'kube-znn-644ff8f5d6-ghq22.167f406b2f1ef32f', 'type': 'Warning', 'message': '0/1 nodes are available: 1 Insufficient cpu.', 'dateevent': '2021-05-15 13:26:59+00:00'}
WARNING:root:{'name': 'kube-znn-644ff8f5d6-r4j2k.167f406b338178e8', 'type': 'Warning', 'message': '0/1 nodes are available: 1 Insufficient cpu.', 'dateevent': '2021-05-15 13:27:00+00:00'}
falha encontrada
falha encontrada
WARNING:root:{'name': 'kube-znn-64cd6996dd-x9dvg.167f406b3ed0ca36', 'type': 'Warning', 'message': '0/1 nodes are available: 1 Insufficient cpu.', 'dateevent': '2021-05-15 13:27:00+00:00'}
falha encontrada
WARNING:root:{'name': 'kube-znn-64cd6996dd-x9dvg.167f406b3ed0ca36', 'type': 'Warning', 'message': '0/1 nodes are available: 1 Insufficient cpu.', 'dateevent': '2021-05-15 13:27:00+00:00'}
falha encontrada
WARNING:root:{'name': 'kube-znn-64cd6996dd-hwj5w.167f406b41aa7ffa', 'type': 'Warning', 'message': '0/1 nodes are available: 1 Insufficient cpu.', 'dateevent': '2021-05-15 13:27:00+00:00'}
WARNING:root:{'name': 'kube-znn-64cd6996dd-hwj5w.167f406b41aa7ffa', 'type': 'Warning', 'message': '0/1 nodes are available: 1 Insufficient cpu.', 'dateevent': '2021-05-15 13:27:00+00:00'}
falha encontrada
falha encontrada
WARNING:root:{'name': 'kube-znn-644ff8f5d6-wtj2f.167f406c5adcb307', 'type': 'Warning', 'message': '0/1 nodes are available: 1 Insufficient cpu.', 'dateevent': '2021-05-15 13:27:05+00:00'}
falha encontrada
WARNING:root:{'name': 'kube-znn-644ff8f5d6-wtj2f.167f406c5adcb307', 'type': 'Warning', 'message': '0/1 nodes are available: 1 Insufficient cpu.', 'dateevent': '2021-05-15 13:27:05+00:00'}
falha encontrada
WARNING:root:{'name': 'kube-znn-644ff8f5d6-7nlbb.167f406c60177353', 'type': 'Warning', 'message': '0/1 nodes are available: 1 Insufficient cpu.', 'dateevent': '2021-05-15 13:27:05+00:00'}
WARNING:root:{'name': 'kube-znn-644ff8f5d6-7nlbb.167f406c60177353', 'type': 'Warning', 'message': '0/1 nodes are available: 1 Insufficient cpu.', 'dateevent': '2021-05-15 13:27:05+00:00'}
falha encontrada
falha encontrada
WARNING:root:{'name': 'kube-znn-64cd6996dd-lr2g4.167f406c6d0cc029', 'type': 'Warning', 'message': '0/1 nodes are available: 1 Insufficient cpu.', 'dateevent': '2021-05-15 13:27:05+00:00'}
falha encontrada
WARNING:root:{'name': 'kube-znn-64cd6996dd-tnmqt.167f406c707bdd17', 'type': 'Warning', 'message': '0/1 nodes are available: 1 Insufficient cpu.', 'dateevent': '2021-05-15 13:27:05+00:00'}
falha encontrada
WARNING:root:{'name': 'kube-znn-64cd6996dd-tnmqt.167f406c707bdd17', 'type': 'Warning', 'message': '0/1 nodes are available: 1 Insufficient cpu.', 'dateevent': '2021-05-15 13:27:05+00:00'}
falha encontrada
WARNING:root:{'name': 'kube-znn-64cd6996dd-lr2g4.167f406c6d0cc029', 'type': 'Warning', 'message': '0/1 nodes are available: 1 Insufficient cpu.', 'dateevent': '2021-05-15 13:27:05+00:00'}
falha encontrada
WARNING:root:{'name': 'kube-znn-64cd6996dd-tnmqt.167f406c707bdd17', 'type': 'Warning', 'message': '0/1 nodes are available: 1 Insufficient cpu.', 'dateevent': '2021-05-15 13:27:05+00:00'}
falha encontrada
WARNING:root:{'name': 'kube-znn-644ff8f5d6-glzcg.167f406d826a5cd8', 'type': 'Warning', 'message': '0/1 nodes are available: 1 Insufficient cpu.', 'dateevent': '2021-05-15 13:27:09+00:00'}
WARNING:root:{'name': 'kube-znn-644ff8f5d6-glzcg.167f406d826a5cd8', 'type': 'Warning', 'message': '0/1 nodes are available: 1 Insufficient cpu.', 'dateevent': '2021-05-15 13:27:09+00:00'}
falha encontrada
WARNING:root:{'name': 'kube-znn-644ff8f5d6-4msgx.167f406d86fc142e', 'type': 'Warning', 'message': '0/1 nodes are available: 1 Insufficient cpu.', 'dateevent': '2021-05-15 13:27:10+00:00'}
falha encontrada
WARNING:root:{'name': 'kube-znn-64cd6996dd-rpdmz.167f406d9109cdfd', 'type': 'Warning', 'message': '0/1 nodes are available: 1 Insufficient cpu.', 'dateevent': '2021-05-15 13:27:10+00:00'}
falha encontrada
WARNING:root:{'name': 'kube-znn-64cd6996dd-xw62v.167f406d9368d293', 'type': 'Warning', 'message': '0/1 nodes are available: 1 Insufficient cpu.', 'dateevent': '2021-05-15 13:27:10+00:00'}
falha encontrada
falha encontrada
WARNING:root:{'name': 'kube-znn-64cd6996dd-rpdmz.167f406d9109cdfd', 'type': 'Warning', 'message': '0/1 nodes are available: 1 Insufficient cpu.', 'dateevent': '2021-05-15 13:27:10+00:00'}
falha encontrada
WARNING:root:{'name': 'kube-znn-64cd6996dd-xw62v.167f406d9368d293', 'type': 'Warning', 'message': '0/1 nodes are available: 1 Insufficient cpu.', 'dateevent': '2021-05-15 13:27:10+00:00'}
falha encontrada
WARNING:root:{'name': 'kube-znn-644ff8f5d6-jqtpf.167f406eacf5c3fb', 'type': 'Warning', 'message': '0/1 nodes are available: 1 Insufficient cpu.', 'dateevent': '2021-05-15 13:27:14+00:00'}
falha encontrada
WARNING:root:{'name': 'kube-znn-644ff8f5d6-jqtpf.167f406eacf5c3fb', 'type': 'Warning', 'message': '0/1 nodes are available: 1 Insufficient cpu.', 'dateevent': '2021-05-15 13:27:14+00:00'}
falha encontrada
WARNING:root:{'name': 'kube-znn-644ff8f5d6-nqh65.167f406eb1b63961', 'type': 'Warning', 'message': '0/1 nodes are available: 1 Insufficient cpu.', 'dateevent': '2021-05-15 13:27:15+00:00'}
falha encontrada
WARNING:root:{'name': 'kube-znn-644ff8f5d6-nqh65.167f406eb1b63961', 'type': 'Warning', 'message': '0/1 nodes are available: 1 Insufficient cpu.', 'dateevent': '2021-05-15 13:27:15+00:00'}
falha encontrada
WARNING:root:{'name': 'kube-znn-64cd6996dd-h9jqz.167f406eb7a8350c', 'type': 'Warning', 'message': '0/1 nodes are available: 1 Insufficient cpu.', 'dateevent': '2021-05-15 13:27:15+00:00'}
falha encontrada
WARNING:root:{'name': 'kube-znn-64cd6996dd-h9jqz.167f406eb7a8350c', 'type': 'Warning', 'message': '0/1 nodes are available: 1 Insufficient cpu.', 'dateevent': '2021-05-15 13:27:15+00:00'}
falha encontrada
WARNING:root:{'name': 'kube-znn-64cd6996dd-czq9z.167f406eba56c9e4', 'type': 'Warning', 'message': '0/1 nodes are available: 1 Insufficient cpu.', 'dateevent': '2021-05-15 13:27:15+00:00'}
falha encontrada
WARNING:root:{'name': 'kube-znn-64cd6996dd-czq9z.167f406eba56c9e4', 'type': 'Warning', 'message': '0/1 nodes are available: 1 Insufficient cpu.', 'dateevent': '2021-05-15 13:27:15+00:00'}
falha encontrada
WARNING:root:{'name': 'kube-znn-644ff8f5d6-tc4s6.167f406fdc59be4a', 'type': 'Warning', 'message': '0/1 nodes are available: 1 Insufficient cpu.', 'dateevent': '2021-05-15 13:27:20+00:00'}
falha encontrada
WARNING:root:{'name': 'kube-znn-644ff8f5d6-tc4s6.167f406fdc59be4a', 'type': 'Warning', 'message': '0/1 nodes are available: 1 Insufficient cpu.', 'dateevent': '2021-05-15 13:27:20+00:00'}
falha encontrada
WARNING:root:{'name': 'kube-znn-64cd6996dd-mbgdb.167f406fe7c92324', 'type': 'Warning', 'message': '0/1 nodes are available: 1 Insufficient cpu.', 'dateevent': '2021-05-15 13:27:20+00:00'}
WARNING:root:{'name': 'kube-znn-64cd6996dd-plmpp.167f406febf5770b', 'type': 'Warning', 'message': '0/1 nodes are available: 1 Insufficient cpu.', 'dateevent': '2021-05-15 13:27:20+00:00'}
falha encontrada
falha encontrada
WARNING:root:{'name': 'kube-znn-64cd6996dd-plmpp.167f406febf5770b', 'type': 'Warning', 'message': '0/1 nodes are available: 1 Insufficient cpu.', 'dateevent': '2021-05-15 13:27:20+00:00'}
falha encontrada
WARNING:root:{'name': 'kube-znn-644ff8f5d6-csp88.167f40710291ce5d', 'type': 'Warning', 'message': '0/1 nodes are available: 1 Insufficient cpu.', 'dateevent': '2021-05-15 13:27:24+00:00'}
falha encontrada
WARNING:root:{'name': 'kube-znn-644ff8f5d6-csp88.167f40710291ce5d', 'type': 'Warning', 'message': '0/1 nodes are available: 1 Insufficient cpu.', 'dateevent': '2021-05-15 13:27:24+00:00'}
falha encontrada
WARNING:root:{'name': 'kube-znn-644ff8f5d6-8tsr4.167f40710a738908', 'type': 'Warning', 'message': '0/1 nodes are available: 1 Insufficient cpu.', 'dateevent': '2021-05-15 13:27:25+00:00'}
falha encontrada
WARNING:root:{'name': 'kube-znn-64cd6996dd-4svgz.167f40710e3291d1', 'type': 'Warning', 'message': '0/1 nodes are available: 1 Insufficient cpu.', 'dateevent': '2021-05-15 13:27:25+00:00'}
falha encontrada
WARNING:root:{'name': 'kube-znn-64cd6996dd-2dww6.167f40711199eaad', 'type': 'Warning', 'message': '0/1 nodes are available: 1 Insufficient cpu.', 'dateevent': '2021-05-15 13:27:25+00:00'}
falha encontrada
WARNING:root:{'name': 'kube-znn-64cd6996dd-2dww6.167f40711199eaad', 'type': 'Warning', 'message': '0/1 nodes are available: 1 Insufficient cpu.', 'dateevent': '2021-05-15 13:27:25+00:00'}
WARNING:root:{'name': 'kube-znn-64cd6996dd-2dww6.167f40711199eaad', 'type': 'Warning', 'message': '0/1 nodes are available: 1 Insufficient cpu.', 'dateevent': '2021-05-15 13:27:25+00:00'}
falha encontrada
falha encontrada
WARNING:root:{'name': 'kube-znn-644ff8f5d6-lc8q8.167f40723121b73f', 'type': 'Warning', 'message': '0/1 nodes are available: 1 Insufficient cpu.', 'dateevent': '2021-05-15 13:27:30+00:00'}
falha encontrada
WARNING:root:{'name': 'kube-znn-644ff8f5d6-lc8q8.167f40723121b73f', 'type': 'Warning', 'message': '0/1 nodes are available: 1 Insufficient cpu.', 'dateevent': '2021-05-15 13:27:30+00:00'}
falha encontrada
WARNING:root:{'name': 'kube-znn-64cd6996dd-4whjs.167f40723d5d7d99', 'type': 'Warning', 'message': '0/1 nodes are available: 1 Insufficient cpu.', 'dateevent': '2021-05-15 13:27:30+00:00'}
falha encontrada
WARNING:root:{'name': 'kube-znn-64cd6996dd-nb494.167f40723fcfa8a8', 'type': 'Warning', 'message': '0/1 nodes are available: 1 Insufficient cpu.', 'dateevent': '2021-05-15 13:27:30+00:00'}
WARNING:root:{'name': 'kube-znn-64cd6996dd-4whjs.167f40723d5d7d99', 'type': 'Warning', 'message': '0/1 nodes are available: 1 Insufficient cpu.', 'dateevent': '2021-05-15 13:27:30+00:00'}
falha encontrada
falha encontrada
WARNING:root:{'name': 'kube-znn-64cd6996dd-nb494.167f40723fcfa8a8', 'type': 'Warning', 'message': '0/1 nodes are available: 1 Insufficient cpu.', 'dateevent': '2021-05-15 13:27:30+00:00'}
WARNING:root:{'name': 'kube-znn-64cd6996dd-nb494.167f40723fcfa8a8', 'type': 'Warning', 'message': '0/1 nodes are available: 1 Insufficient cpu.', 'dateevent': '2021-05-15 13:27:30+00:00'}
falha encontrada
falha encontrada
WARNING:root:{'name': 'kube-znn-64cd6996dd-4whjs.167f40723d5d7d99', 'type': 'Warning', 'message': '0/1 nodes are available: 1 Insufficient cpu.', 'dateevent': '2021-05-15 13:27:30+00:00'}
falha encontrada
WARNING:root:{'name': 'kube-znn-64cd6996dd-4whjs.167f40723d5d7d99', 'type': 'Warning', 'message': '0/1 nodes are available: 1 Insufficient cpu.', 'dateevent': '2021-05-15 13:27:30+00:00'}
falha encontrada
WARNING:root:{'name': 'kube-znn-64cd6996dd-r5g2h.167f4075687e982b', 'type': 'Warning', 'message': '0/1 nodes are available: 1 Insufficient cpu.', 'dateevent': '2021-05-15 13:27:43+00:00'}
falha encontrada
WARNING:root:{'name': 'kube-znn-64cd6996dd-r5g2h.167f4075687e982b', 'type': 'Warning', 'message': '0/1 nodes are available: 1 Insufficient cpu.', 'dateevent': '2021-05-15 13:27:43+00:00'}
